Workbook

Sheet  Bem-vindo
A1: =SumWorld!A1 -> Prezado(a) usuário(a): Esta é a versão de 7 de novembro de 2014, às 11h, da planilha de 2052 de Ulrich Goluke (2052@blue-way.net)
A3: As folhas contêm os dados do livro 2052 de Jorgen Randers.
A4: Listamos as fontes e você pode ver as fórmulas que usamos.
A5: Além disso, você pode criar sua própria previsão, alterando as células que estão sobrepostas em amarelo.
A6: Você não pode alterar nenhuma outra célula.
A7: A planilha SumWorld soma automaticamente as 5 regiões. Portanto, se você quiser alterar o mundo, precisa começar pelas regiões.
A8: Utilizamos o seguinte código de cores:
A9: Dados históricos | D9: Sua previsão
A10: Previsão de Randers | D10: Calculado a partir da sua previsão.
A11: Valores calculados | D11: Suas próprias células de referência
A13: Se encontrar algum erro, por favor, nos avise: 2052@blue-way.net

Sheet  EUA
A1: =SumWorld!A1 -> Prezado(a) usuário(a): Esta é a versão de 7 de novembro de 2014, às 11h, da planilha de 2052 de Ulrich Goluke (2052@blue-way.net)
A2: =SumWorld!A2 -> Prezado(a) usuário(a): O lado esquerdo desta planilha contém os dados numéricos e os gráficos que você também encontra no livro de 2052. | U2: =SumWorld!U2 -> Prezado(a) usuário(a): Os cálculos nesta parte à direita da planilha garantem o dimensionamento correto dos gráficos.
U3: =SumWorld!U3 -> Contém também a fonte dos dados históricos.
I4: Código de cores | J4: Dados históricos | M4: Sua previsão
A5: EUA | J5: Previsão de Randers | M5: Calculado a partir da sua previsão.
J6: Valores calculados | M6: Suas próprias células de referência
A7: =CONCATENATE("Graph 1. Population - ",A5," 1970 to 2050") -> Gráfico 1. População - EUA, de 1970 a 2050
B8: 1970 | C8: 1975 | D8: 1980 | E8: 1985 | F8: 1990 | G8: 1995 | H8: 2000 | I8: 2005 | J8: 2010 | K8: 2015 | L8: 2020 | M8: 2025 | N8: 2030 | O8: 2035 | P8: 2040 | Q8: 2045 | R8: 2050 | S8: Unidades
A9: População, EUA | B9: 212.24347 | C9: 222.13306 | D9: 233.11944 | E9: 244.60382 | F9: 256.97116 | G9: 270.13235 | H9: 286.41917 | I9: 300.71164 | J9: 314.24201 | K9: =J9+(J10-J11)*5 -> 322.55952 | L9: =K9+(K10-K11)*5 -> 329.63188 | M9: =L9+(L10-L11)*5 -> 335.65485 | N9: =M9+(M10-M11)*5 -> 340.26105 | O9: =N9+(N10-N11)*5 -> 343.10315 | P9: =O9+(O10-O11)*5 -> 344.01756 | Q9: =P9+(P10-P11)*5 -> 343.15168 | R9: =Q9+(Q10-Q11)*5 -> 340.81722 | S9: Deputado | U9: A tabela original foi baixada de http://esa.un.org/unpd/wpp/Excel-Data/DB03_Population_ByAgeSex_Quinquennial/WPP2010_DB3_F1_POPULATION_BY_AGE_BOTH_SEXES.XLS
A10: Nascimentos, EUA | B10: 3.4435702 | C10: 3.4555056 | D10: 3.7199186 | E10: 3.936335 | F10: 4.030714 | G10: 3.943802 | H10: 4.1353104 | I10: 4.2960796 | J10: =J9*J12/100 -> 4.3365398 | K10: =K9*K12/100 -> 4.1932737 | L10: =L9*L12/100 -> 4.1203985 | M10: =M9*M12/100 -> 4.0278582 | N10: =N9*N12/100 -> 3.9130021 | O10: =O9*O12/100 -> 3.7741346 | P10: =P9*P12/100 -> 3.6121844 | Q10: =Q9*Q12/100 -> 3.4315168 | R10: =R9*R12/100 -> 3.2377636 | S10: Mp/ano | U10: Último acesso em 11 de abril de 2012
A11: Mortes, EUA | B11: 1.9959064 | C11: 1.9594826 | D11: 2.0725094 | E11: 2.206858 | F11: 2.288043 | G11: 2.3846672 | H11: 2.4844 | I11: 2.5512516 | J11: =J9*J13/100 -> 2.6730392 | K11: =K9*K13/100 -> 2.7788004 | L11: =L9*L13/100 -> 2.915805 | M11: =M9*M13/100 -> 3.1066172 | N11: =N9*N13/100 -> 3.3445838 | O11: =O9*O13/100 -> 3.5912513 | P11: =P9*P13/100 -> 3.7853617 | Q11: =Q9*Q13/100 -> 3.8984084 | R11: =R9*R13/100 -> 3.928395 | S11: Mp/ano | U11: Para valores futuros, foi utilizada a variante BAIXA.
A12: taxa bruta de natalidade | B12: =B10/B9*100 -> 1.6224622 | C12: =C10/C9*100 -> 1.5556017 | D12: =D10/D9*100 -> 1.5957136 | E12: =E10/E9*100 -> 1.6092696 | F12: =F10/F9*100 -> 1.5685472 | G12: =G10/G9*100 -> 1.4599517 | H12: =H10/H9*100 -> 1.4437966 | I12: =I10/I9*100 -> 1.4286376 | J12: 1.38 | K12: 1.3 | L12: 1.25 | M12: 1.2 | N12: 1.15 | O12: 1.1 | P12: 1.05 | Q12: 1 | R12: 0.95 | S12: % por ano
A13: taxa bruta de mortalidade | B13: =B11/B9*100 -> 0.94038528 | C13: =C11/C9*100 -> 0.88212111 | D13: =D11/D9*100 -> 0.88903329 | E13: =E11/E9*100 -> 0.9022173 | F13: =F11/F9*100 -> 0.89038901 | G13: =G11/G9*100 -> 0.88277734 | H13: =H11/H9*100 -> 0.86740003 | I13: =I11/I9*100 -> 0.84840466 | J13: 0.85063075 | K13: 0.86148456 | L13: 0.88456402 | M13: 0.92553918 | N13: 0.9829464 | O13: 1.0466973 | P13: 1.1003397 | Q13: 1.1360598 | R13: 1.1526398 | S13: % por ano
A14: Sua previsão
G15: taxa bruta de natalidade | I15: Sua previsão | J15: 1.38 | K15: =K12*0.98 -> 1.274 | L15: =L12*0.98 -> 1.225 | M15: =M12*0.98 -> 1.176 | N15: =N12*0.98 -> 1.127 | O15: =O12*0.98 -> 1.078 | P15: =P12*0.98 -> 1.029 | Q15: =Q12*0.98 -> 0.98 | R15: =R12*0.98 -> 0.931 | S15: % por ano
G16: taxa bruta de mortalidade | I16: Sua previsão | J16: 0.85 | K16: =K13*0.98 -> 0.84425487 | L16: =L13*0.98 -> 0.86687274 | M16: =M13*0.98 -> 0.9070284 | N16: =N13*0.98 -> 0.96328748 | O16: =O13*0.98 -> 1.0257633 | P16: =P13*0.98 -> 1.0783329 | Q16: =Q13*0.98 -> 1.1133386 | R16: =R13*0.98 -> 1.129587 | S16: % por ano
I17: População, EUA | K17: =J9+(J18-J19)*5 -> 322.56943 | L17: =K17+(K18-K19)*5 -> 329.50056 | M17: =L17+(L18-L19)*5 -> 335.40071 | N17: =M17+(M18-M19)*5 -> 339.91138 | O17: =N17+(N18-N19)*5 -> 342.69377 | P17: =O17+(O18-O19)*5 -> 343.58882 | Q17: =P17+(P18-P19)*5 -> 342.74131 | R17: =Q17+(Q18-Q19)*5 -> 340.45628 | S17: Deputado
I18: Nascimentos, EUA | J18: =J9*J15/100 -> 4.3365398 | K18: =K17*K15/100 -> 4.1095345 | L18: =L17*L15/100 -> 4.0363818 | M18: =M17*M15/100 -> 3.9443124 | N18: =N17*N15/100 -> 3.8308012 | O18: =O17*O15/100 -> 3.6942388 | P18: =P17*P15/100 -> 3.535529 | Q18: =Q17*Q15/100 -> 3.3588649 | R18: =R17*R15/100 -> 3.169648 | S18: Mp/ano
I19: Mortes, EUA | J19: =J9*J16/100 -> 2.6710571 | K19: =K17*K16/100 -> 2.7233081 | L19: =L17*L16/100 -> 2.8563505 | M19: =M17*M16/100 -> 3.0421797 | N19: =N17*N16/100 -> 3.2743237 | O19: =O17*O16/100 -> 3.515227 | P19: =P17*P16/100 -> 3.7050312 | Q19: =Q17*Q16/100 -> 3.8158715 | R19: =R17*R16/100 -> 3.8457499 | S19: Mp/ano
A20: Apenas para fins informativos
A21: Previsão baixa da população da ONU | K21: 325.10048 | L21: 334.00151 | M21: 341.17873 | N21: 347.55097 | O21: 352.96979 | P21: 357.08974 | Q21: 359.48494 | R21: 360.24558 | S21: Deputado
A22: Nascimentos: baixa previsão da ONU | J22: 3.8694828 | K22: 3.6454144 | L22: 3.4878694 | M22: 3.5298724 | N22: 3.595832 | O22: 3.6132888 | P22: 3.5047634 | Q22: 3.3347716 | R22: 3.2161554 | S22: Mp/ano
A23: Mortes: previsão baixa da ONU | J23: 2.6730392 | K23: 2.8006904 | L23: 2.9544572 | M23: 3.1577428 | N23: 3.4162398 | O23: 3.6945252 | P23: 3.9292 | Q23: 4.083964 | R23: 4.152334 | S23: Mp/ano
A24: Baixa taxa de natalidade da ONU | J24: =J22/J9*100 -> 1.2313703 | K24: =K22/K21*100 -> 1.1213193 | L24: =L22/L21*100 -> 1.0442676 | M24: =M22/M21*100 -> 1.0346109 | N24: =N22/N21*100 -> 1.03462 | O24: =O22/O21*100 -> 1.0236822 | P24: =P22/P21*100 -> 0.98147974 | Q24: =Q22/Q21*100 -> 0.92765266 | R24: =R22/R21*100 -> 0.89276748 | S24: % por ano
A25: Baixa taxa de mortalidade da ONU | J25: =J23/J9*100 -> 0.85063075 | K25: =K23/K21*100 -> 0.86148456 | L25: =L23/L21*100 -> 0.88456402 | M25: =M23/M21*100 -> 0.92553918 | N25: =N23/N21*100 -> 0.9829464 | O25: =O23/O21*100 -> 1.0466973 | P25: =P23/P21*100 -> 1.1003397 | Q25: =Q23/Q21*100 -> 1.1360598 | R25: =R23/R21*100 -> 1.1526398 | S25: % por ano | X25: Prezado(a) usuário(a): Utilize a tabela amarela abaixo para definir o valor máximo nos eixos verticais do gráfico.
E26: Para taxas: o valor inserido no ano n é o valor médio anual entre n e n+5. | V26: Valor máximo no eixo vertical | AA26: Cálculos realizados para ajustar todas as variáveis para valores entre 0 e 1.
U27: Para o gráfico à esquerda, nomes das variáveis (unidade) | V27: nos gráficos originais de Randers | W27: Na sua previsão | AB27: 1970 | AC27: 1975 | AD27: 1980 | AE27: 1985 | AF27: 1990 | AG27: 1995 | AH27: 2000 | AI27: 2005 | AJ27: 2010 | AK27: 2015 | AL27: 2020 | AM27: 2025 | AN27: 2030 | AO27: 2035 | AP27: 2040 | AQ27: 2045 | AR27: 2050
U28: =AA28 -> População, EUA (0 - 0,35 Gp) | V28: 350 | W28: =W38 -> 350 | AA28: =CONCATENATE(A9," (0 - ",W28/1000," Gp)") -> População, EUA (0 - 0,35 Gp) | AB28: =B9/$W28 -> 0.60640993 | AC28: =C9/$W28 -> 0.63466588 | AD28: =D9/$W28 -> 0.66605554 | AE28: =E9/$W28 -> 0.69886806 | AF28: =F9/$W28 -> 0.73420333 | AG28: =G9/$W28 -> 0.77180672 | AH28: =H9/$W28 -> 0.8183405 | AI28: =I9/$W28 -> 0.85917613 | ... AR28: =R9/$W28 -> 0.97376348
U29: =AA29 -> Nascimentos, EUA (0 - 9 milhões/ano) | V29: 7 | W29: =W39 -> 9 | AA29: =CONCATENATE(A10," (0 - ",W29," Mp / yr)") -> Nascimentos, EUA (0 - 9 milhões/ano) | AB29: =B10/$W29 -> 0.38261891 | AC29: =C10/$W29 -> 0.38394507 | AD29: =D10/$W29 -> 0.41332429 | AE29: =E10/$W29 -> 0.43737056 | AF29: =F10/$W29 -> 0.44785711 | AG29: =G10/$W29 -> 0.43820022 | AH29: =H10/$W29 -> 0.45947893 | AI29: =I10/$W29 -> 0.47734218 | ... AR29: =R10/$W29 -> 0.35975151
U30: =AA30 -> Mortes, EUA (0 - 5 milhões/ano) | V30: 5 | W30: =W40 -> 5 | AA30: =CONCATENATE(A11," (0 - ",W30," Mp / yr)") -> Mortes, EUA (0 - 5 milhões/ano) | AB30: =B11/$W30 -> 0.39918128 | AC30: =C11/$W30 -> 0.39189652 | AD30: =D11/$W30 -> 0.41450188 | AE30: =E11/$W30 -> 0.4413716 | AF30: =F11/$W30 -> 0.4576086 | AG30: =G11/$W30 -> 0.47693344 | AH30: =H11/$W30 -> 0.49688 | AI30: =I11/$W30 -> 0.51025032 | ... AR30: =R11/$W30 -> 0.78567899
U31: =AA31 -> Taxa bruta de natalidade (0 - 2 % / ano) | V31: 2 | W31: =W41 -> 2 | AA31: =CONCATENATE(A12," (0 - ",W31," % / yr)") -> Taxa bruta de natalidade (0 - 2 % / ano) | AB31: =B12/$W31 -> 0.81123111 | AC31: =C12/$W31 -> 0.77780084 | AD31: =D12/$W31 -> 0.79785681 | AE31: =E12/$W31 -> 0.80463481 | AF31: =F12/$W31 -> 0.7842736 | AG31: =G12/$W31 -> 0.72997587 | AH31: =H12/$W31 -> 0.72189832 | AI31: =I12/$W31 -> 0.7143188 | ... AR31: =R12/$W31 -> 0.475
U32: =AA32 -> Taxa bruta de mortalidade (0 - 2 % / ano) | V32: 2 | W32: =W42 -> 2 | AA32: =CONCATENATE(A13," (0 - ",W32," % / yr)") -> Taxa bruta de mortalidade (0 - 2 % / ano) | AB32: =B13/$W32 -> 0.47019264 | AC32: =C13/$W32 -> 0.44106055 | AD32: =D13/$W32 -> 0.44451664 | AE32: =E13/$W32 -> 0.45110865 | AF32: =F13/$W32 -> 0.4451945 | AG32: =G13/$W32 -> 0.44138867 | AH32: =H13/$W32 -> 0.43370001 | AI32: =I13/$W32 -> 0.42420233 | ... AR32: =R13/$W32 -> 0.57631991
U33: =AA33 -> Previsão de baixa população da ONU (0 - 0,35 Gp) | W33: =W28 -> 350 | AA33: =CONCATENATE(A21," (0 - ",W33/1000," Gp)") -> Previsão de baixa população da ONU (0 - 0,35 Gp) | AK33: =K21/$W33 -> 0.9288585 | AL33: =L21/$W33 -> 0.95429003 | AM33: =M21/$W33 -> 0.97479636 | AN33: =N21/$W33 -> 0.99300278 | AO33: =O21/$W33 -> 1.0084851 | AP33: =P21/$W33 -> 1.0202564 | AQ33: =Q21/$W33 -> 1.0270998 | AR33: =R21/$W33 -> 1.0292731
U34: =AA34 -> Nascimentos: Previsão baixa da ONU (0 - 9 milhões/ano) | W34: =W29 -> 9 | AA34: =CONCATENATE(A22," (0 - ",W34," Mp / yr)") -> Nascimentos: Previsão baixa da ONU (0 - 9 milhões/ano) | AJ34: =J22/$W34 -> 0.42994253 | AK34: =K22/$W34 -> 0.40504604 | AL34: =L22/$W34 -> 0.38754104 | AM34: =M22/$W34 -> 0.39220804 | AN34: =N22/$W34 -> 0.39953689 | AO34: =O22/$W34 -> 0.40147653 | AP34: =P22/$W34 -> 0.38941816 | AQ34: =Q22/$W34 -> 0.37053018 | AR34: =R22/$W34 -> 0.3573506
U35: =AA35 -> Mortes: Previsão mínima da ONU (0 - 5 milhões/ano) | W35: =W30 -> 5 | AA35: =CONCATENATE(A23," (0 - ",W35," Mp / yr)") -> Mortes: Previsão mínima da ONU (0 - 5 milhões/ano) | AJ35: =J23/$W35 -> 0.53460784 | AK35: =K23/$W35 -> 0.56013808 | AL35: =L23/$W35 -> 0.59089144 | AM35: =M23/$W35 -> 0.63154856 | AN35: =N23/$W35 -> 0.68324796 | AO35: =O23/$W35 -> 0.73890504 | AP35: =P23/$W35 -> 0.78584 | AQ35: =Q23/$W35 -> 0.8167928 | AR35: =R23/$W35 -> 0.8304668
U36: =AA36 -> Baixa taxa de natalidade da ONU (0 - 2% / ano) | W36: =W31 -> 2 | AA36: =CONCATENATE(A24," (0 - ",W36," % / yr)") -> Baixa taxa de natalidade da ONU (0 - 2% / ano) | AJ36: =J24/$W36 -> 0.61568515 | AK36: =K24/$W36 -> 0.56065965 | AL36: =L24/$W36 -> 0.52213378 | AM36: =M24/$W36 -> 0.51730547 | AN36: =N24/$W36 -> 0.51731002 | AO36: =O24/$W36 -> 0.51184108 | AP36: =P24/$W36 -> 0.49073987 | AQ36: =Q24/$W36 -> 0.46382633 | AR36: =R24/$W36 -> 0.44638374
U37: =AA37 -> Baixa taxa de mortalidade da ONU (0 - 2% / ano) | W37: =W32 -> 2 | AA37: =CONCATENATE(A25," (0 - ",W37," % / yr)") -> Baixa taxa de mortalidade da ONU (0 - 2% / ano) | AJ37: =J25/$W37 -> 0.42531538 | AK37: =K25/$W37 -> 0.43074228 | AL37: =L25/$W37 -> 0.44228201 | AM37: =M25/$W37 -> 0.46276959 | AN37: =N25/$W37 -> 0.4914732 | AO37: =O25/$W37 -> 0.52334864 | AP37: =P25/$W37 -> 0.55016983 | AQ37: =Q25/$W37 -> 0.56802992 | AR37: =R25/$W37 -> 0.57631991
U38: =AA38 -> População, EUA Sua previsão (0 - 0,35 Gp) | W38: 350 | AA38: =CONCATENATE(A9," Your forecast (0 - ",W38/1000," Gp)") -> População, EUA Sua previsão (0 - 0,35 Gp) | AK38: =K17/$W38 -> 0.92162693 | AL38: =L17/$W38 -> 0.94143017 | AM38: =M17/$W38 -> 0.95828776 | AN38: =N17/$W38 -> 0.97117537 | AO38: =O17/$W38 -> 0.97912504 | AP38: =P17/$W38 -> 0.98168236 | AQ38: =Q17/$W38 -> 0.9792609 | AR38: =R17/$W38 -> 0.97273223
U39: =AA39 -> Nascimentos, EUA Sua previsão (0 - 9 milhões/ano) | W39: 9 | AA39: =CONCATENATE(A10," Your forecast (0 - ",W39," Mp / yr)") -> Nascimentos, EUA Sua previsão (0 - 9 milhões/ano) | AJ39: =J18/$W39 -> 0.48183775 | AK39: =K18/$W39 -> 0.45661494 | AL39: =L18/$W39 -> 0.44848687 | AM39: =M18/$W39 -> 0.43825693 | AN39: =N18/$W39 -> 0.42564458 | AO39: =O18/$W39 -> 0.41047098 | AP39: =P18/$W39 -> 0.39283656 | AQ39: =Q18/$W39 -> 0.37320721 | AR39: =R18/$W39 -> 0.35218311
U40: =AA40 -> Mortes, EUA Sua previsão (0 - 5 milhões/ano) | W40: 5 | AA40: =CONCATENATE(A11," Your forecast (0 - ",W40," Mp / yr)") -> Mortes, EUA Sua previsão (0 - 5 milhões/ano) | AJ40: =J19/$W40 -> 0.53421142 | AK40: =K19/$W40 -> 0.54466162 | AL40: =L19/$W40 -> 0.5712701 | AM40: =M19/$W40 -> 0.60843595 | AN40: =N19/$W40 -> 0.65486475 | AO40: =O19/$W40 -> 0.7030454 | AP40: =P19/$W40 -> 0.74100625 | AQ40: =Q19/$W40 -> 0.76317429 | AR40: =R19/$W40 -> 0.76914999
...

Sheet  China
A1: =SumWorld!A1 -> Prezado(a) usuário(a): Esta é a versão de 7 de novembro de 2014, às 11h, da planilha de 2052 de Ulrich Goluke (2052@blue-way.net)
A2: =SumWorld!A2 -> Prezado(a) usuário(a): O lado esquerdo desta planilha contém os dados numéricos e os gráficos que você também encontra no livro de 2052. | U2: =SumWorld!U2 -> Prezado(a) usuário(a): Os cálculos nesta parte à direita da planilha garantem o dimensionamento correto dos gráficos.
U3: =SumWorld!U3 -> Contém também a fonte dos dados históricos.
I4: Código de cores | J4: Dados históricos | M4: Sua previsão
A5: China | J5: Previsão de Randers | M5: Calculado a partir da sua previsão.
J6: Valores calculados | M6: Suas próprias células de referência
A7: =CONCATENATE("Graph 1. Population - ",A5," 1970 to 2050") -> Gráfico 1. População - China de 1970 a 2050
B8: 1970 | C8: 1975 | D8: 1980 | E8: 1985 | F8: 1990 | G8: 1995 | H8: 2000 | I8: 2005 | J8: 2010 | K8: 2015 | L8: 2020 | M8: 2025 | N8: 2030 | O8: 2035 | P8: 2040 | Q8: 2045 | R8: 2050 | S8: Unidades
A9: População, China | B9: 818.83193 | C9: 919.64437 | D9: 988.47042 | E9: 1062.2901 | F9: 1151.3488 | G9: 1220.5294 | H9: 1276.3319 | I9: 1314.8847 | J9: 1348.932 | K9: =J9+(J10-J11)*5 -> 1365.714 | L9: =K9+(K10-K11)*5 -> 1369.453 | M9: =L9+(L10-L11)*5 -> 1361.3042 | N9: =M9+(M10-M11)*5 -> 1342.9732 | O9: =N9+(N10-N11)*5 -> 1313.2993 | P9: =O9+(O10-O11)*5 -> 1273.0927 | Q9: =P9+(P10-P11)*5 -> 1223.4945 | R9: =Q9+(Q10-Q11)*5 -> 1165.5953 | S9: Deputado | U9: A tabela original foi baixada de http://esa.un.org/unpd/wpp/Excel-Data/DB03_Population_ByAgeSex_Quinquennial/WPP2010_DB3_F1_POPULATION_BY_AGE_BOTH_SEXES.XLS
A10: Nascimentos, China | B10: 27.270017 | C10: 20.554883 | D10: 21.977709 | E10: 25.618699 | F10: 22.181769 | G10: 19.86874 | H10: 17.411251 | I10: 16.775341 | J10: =J9*J12/100 -> 13.48932 | K10: =K9*K12/100 -> 11.608569 | L10: =L9*L12/100 -> 10.270898 | M10: =M9*M12/100 -> 9.5291296 | N10: =N9*N12/100 -> 8.729326 | O10: =O9*O12/100 -> 8.1424556 | P10: =P9*P12/100 -> 7.6385564 | Q10: =Q9*Q12/100 -> 7.0962678 | R10: =R9*R12/100 -> 6.5273339 | S10: Mp/ano | U10: Último acesso em 11 de abril de 2012
A11: Mortes, China | B11: 6.8967402 | C11: 6.7831322 | D11: 7.1851182 | E11: 7.799106 | F11: 8.2157398 | G11: 8.686851 | H11: 9.2473254 | I11: 9.6344188 | J11: =J9*J13/100 -> 10.132919 | K11: =K9*K13/100 -> 10.860764 | L11: =L9*L13/100 -> 11.900656 | M11: =M9*M13/100 -> 13.195331 | N11: =N9*N13/100 -> 14.664115 | O11: =O9*O13/100 -> 16.183766 | P11: =P9*P13/100 -> 17.558212 | Q11: =Q9*Q13/100 -> 18.67609 | R11: =R9*R13/100 -> 19.397969 | S11: Mp/ano | U11: Para valores futuros, foi utilizada a variante BAIXA.
A12: taxa bruta de natalidade | B12: =B10/B9*100 -> 3.3303558 | C12: =C10/C9*100 -> 2.2350904 | D12: =D10/D9*100 -> 2.2234059 | E12: =E10/E9*100 -> 2.4116482 | F12: =F10/F9*100 -> 1.9265898 | G12: =G10/G9*100 -> 1.6278789 | H12: =H10/H9*100 -> 1.3641632 | I12: =I10/I9*100 -> 1.2758032 | J12: 1 | K12: 0.85 | L12: 0.75 | M12: 0.7 | N12: 0.65 | O12: 0.62 | P12: 0.6 | Q12: 0.58 | R12: 0.56 | S12: % por ano
A13: taxa bruta de mortalidade | B13: =B11/B9*100 -> 0.84226567 | C13: =C11/C9*100 -> 0.73758209 | D13: =D11/D9*100 -> 0.72689258 | E13: =E11/E9*100 -> 0.73417857 | F13: =F11/F9*100 -> 0.71357523 | G13: =G11/G9*100 -> 0.71172815 | H13: =H11/H9*100 -> 0.72452355 | I13: =I11/I9*100 -> 0.73271965 | J13: 0.75118086 | K13: 0.79524442 | L13: 0.86900795 | M13: 0.96931538 | N13: 1.0919141 | O13: 1.2322984 | P13: 1.3791778 | Q13: 1.5264548 | R13: 1.6642113 | S13: % por ano
A14: Sua previsão
G15: taxa bruta de natalidade | I15: Sua previsão | J15: =J12 -> 1 | K15: =K12*0.98 -> 0.833 | L15: =L12*0.98 -> 0.735 | M15: =M12*0.98 -> 0.686 | N15: =N12*0.98 -> 0.637 | O15: =O12*0.98 -> 0.6076 | P15: =P12*0.98 -> 0.588 | Q15: =Q12*0.98 -> 0.5684 | R15: =R12*0.98 -> 0.5488 | S15: % por ano
G16: taxa bruta de mortalidade | I16: Sua previsão | J16: =J13 -> 0.75118086 | K16: =K13*0.98 -> 0.77933953 | L16: =L13*0.98 -> 0.85162779 | M16: =M13*0.98 -> 0.94992907 | N16: =N13*0.98 -> 1.0700759 | O16: =O13*0.98 -> 1.2076524 | P16: =P13*0.98 -> 1.3515942 | Q16: =Q13*0.98 -> 1.4959257 | R16: =R13*0.98 -> 1.630927 | S16: % por ano
I17: População, China | K17: =J9+(J18-J19)*5 -> 1365.714 | L17: =K17+(K18-K19)*5 -> 1369.3782 | M17: =L17+(L18-L19)*5 -> 1361.3929 | N17: =M17+(M18-M19)*5 -> 1343.4273 | O17: =N17+(N18-N19)*5 -> 1314.337 | P17: =O17+(O18-O19)*5 -> 1274.9035 | Q17: =P17+(P18-P19)*5 -> 1226.228 | R17: =Q17+(Q18-Q19)*5 -> 1169.3601 | S17: Deputado
I18: Nascimentos, China | J18: =J9*J15/100 -> 13.48932 | K18: =K17*K15/100 -> 11.376398 | L18: =L17*L15/100 -> 10.06493 | M18: =M17*M15/100 -> 9.3391551 | N18: =N17*N15/100 -> 8.557632 | O18: =O17*O15/100 -> 7.9859117 | P18: =P17*P15/100 -> 7.4964323 | Q18: =Q17*Q15/100 -> 6.96988 | R18: =R17*R15/100 -> 6.4174483 | S18: Mp/ano
I19: Mortes, China | J19: =J9*J16/100 -> 10.132919 | K19: =K17*K16/100 -> 10.643549 | L19: =L17*L16/100 -> 11.662006 | M19: =M17*M16/100 -> 12.932267 | N19: =N17*N16/100 -> 14.375691 | O19: =O17*O16/100 -> 15.872623 | P19: =P17*P16/100 -> 17.231521 | Q19: =Q17*Q16/100 -> 18.34346 | R19: =R17*R16/100 -> 19.07141 | S19: Mp/ano
A20: Apenas para fins informativos
A21: Previsão baixa da população da ONU | K21: 1364.9973 | L21: 1364.0839 | M21: 1349.8009 | N21: 1327.5762 | O21: 1296.0858 | P21: 1253.7035 | Q21: 1200.786 | R21: 1139.2767 | S21: Deputado
A22: Nascimentos: baixa previsão da ONU | J22: 13.630771 | K22: 10.987687 | L22: 9.3017772 | M22: 8.9286392 | N22: 8.487085 | O22: 7.78629 | P22: 6.9977326 | Q22: 6.3185652 | R22: 5.815751 | S22: Mp/ano
A23: Mortes: previsão baixa da ONU | J23: 10.132919 | K23: 10.855065 | L23: 11.853998 | M23: 13.083827 | N23: 14.495993 | O23: 15.971644 | P23: 17.290799 | Q23: 18.329456 | R23: 18.959972 | S23: Mp/ano
A24: Baixa taxa de natalidade da ONU | J24: =J22/J9*100 -> 1.0104862 | K24: =K22/K21*100 -> 0.80496037 | L24: =L22/L21*100 -> 0.68190653 | M24: =M22/M21*100 -> 0.66147825 | N24: =N22/N21*100 -> 0.63929173 | O24: =O22/O21*100 -> 0.60075422 | P24: =P22/P21*100 -> 0.5581649 | Q24: =Q22/Q21*100 -> 0.52620243 | R24: =R22/R21*100 -> 0.51047746 | S24: % por ano
A25: Baixa taxa de mortalidade da ONU | J25: =J23/J9*100 -> 0.75118086 | K25: =K23/K21*100 -> 0.79524442 | L25: =L23/L21*100 -> 0.86900795 | M25: =M23/M21*100 -> 0.96931538 | N25: =N23/N21*100 -> 1.0919141 | O25: =O23/O21*100 -> 1.2322984 | P25: =P23/P21*100 -> 1.3791778 | Q25: =Q23/Q21*100 -> 1.5264548 | R25: =R23/R21*100 -> 1.6642113 | S25: % por ano | X25: Prezado(a) usuário(a): Utilize a tabela amarela abaixo para definir o valor máximo nos eixos verticais do gráfico.
E26: Para taxas: o valor inserido no ano n é o valor médio anual entre n e n+5. | V26: Valor máximo no eixo vertical | AA26: Cálculos realizados para ajustar todas as variáveis para valores entre 0 e 1.
U27: Para o gráfico à esquerda, nomes das variáveis (unidade) | V27: nos gráficos originais de Randers | W27: Na sua previsão | AB27: 1970 | AC27: 1975 | AD27: 1980 | AE27: 1985 | AF27: 1990 | AG27: 1995 | AH27: 2000 | AI27: 2005 | AJ27: 2010 | AK27: 2015 | AL27: 2020 | AM27: 2025 | AN27: 2030 | AO27: 2035 | AP27: 2040 | AQ27: 2045 | AR27: 2050
U28: =AA28 -> População da China (0 - 1,4 Gp) | V28: 1400 | W28: =W38 -> 1400 | AA28: =CONCATENATE(A9," (0 - ",W28/1000," Gp)") -> População da China (0 - 1,4 Gp) | AB28: =B9/$W28 -> 0.58487995 | AC28: =C9/$W28 -> 0.65688884 | AD28: =D9/$W28 -> 0.7060503 | AE28: =E9/$W28 -> 0.75877861 | AF28: =F9/$W28 -> 0.822392 | AG28: =G9/$W28 -> 0.87180668 | AH28: =H9/$W28 -> 0.91166566 | AI28: =I9/$W28 -> 0.93920338 | ... AR28: =R9/$W28 -> 0.8325681
U29: =AA29 -> Nascimentos, China (0 - 30 milhões/ano) | V29: 30 | W29: =W39 -> 30 | AA29: =CONCATENATE(A10," (0 - ",W29," Mp / yr)") -> Nascimentos, China (0 - 30 milhões/ano) | AB29: =B10/$W29 -> 0.90900056 | AC29: =C10/$W29 -> 0.68516277 | AD29: =D10/$W29 -> 0.73259031 | AE29: =E10/$W29 -> 0.85395662 | AF29: =F10/$W29 -> 0.73939229 | AG29: =G10/$W29 -> 0.66229133 | AH29: =H10/$W29 -> 0.58037503 | AI29: =I10/$W29 -> 0.55917803 | ... AR29: =R10/$W29 -> 0.2175778
U30: =AA30 -> Mortes, China (0 - 20 milhões/ano) | V30: 20 | W30: =W40 -> 20 | AA30: =CONCATENATE(A11," (0 - ",W30," Mp / yr)") -> Mortes, China (0 - 20 milhões/ano) | AB30: =B11/$W30 -> 0.34483701 | AC30: =C11/$W30 -> 0.33915661 | AD30: =D11/$W30 -> 0.35925591 | AE30: =E11/$W30 -> 0.3899553 | AF30: =F11/$W30 -> 0.41078699 | AG30: =G11/$W30 -> 0.43434255 | AH30: =H11/$W30 -> 0.46236627 | AI30: =I11/$W30 -> 0.48172094 | ... AR30: =R11/$W30 -> 0.96989845
U31: =AA31 -> Taxa bruta de natalidade (0 - 4 % / ano) | V31: 4 | W31: =W41 -> 4 | AA31: =CONCATENATE(A12," (0 - ",W31," % / yr)") -> Taxa bruta de natalidade (0 - 4 % / ano) | AB31: =B12/$W31 -> 0.83258896 | AC31: =C12/$W31 -> 0.5587726 | AD31: =D12/$W31 -> 0.55585146 | AE31: =E12/$W31 -> 0.60291204 | AF31: =F12/$W31 -> 0.48164746 | AG31: =G12/$W31 -> 0.40696973 | AH31: =H12/$W31 -> 0.34104081 | AI31: =I12/$W31 -> 0.31895079 | ... AR31: =R12/$W31 -> 0.14
U32: =AA32 -> Taxa bruta de mortalidade (0 - 2 % / ano) | V32: 2 | W32: =W42 -> 2 | AA32: =CONCATENATE(A13," (0 - ",W32," % / yr)") -> Taxa bruta de mortalidade (0 - 2 % / ano) | AB32: =B13/$W32 -> 0.42113283 | AC32: =C13/$W32 -> 0.36879105 | AD32: =D13/$W32 -> 0.36344629 | AE32: =E13/$W32 -> 0.36708929 | AF32: =F13/$W32 -> 0.35678761 | AG32: =G13/$W32 -> 0.35586408 | AH32: =H13/$W32 -> 0.36226178 | AI32: =I13/$W32 -> 0.36635982 | ... AR32: =R13/$W32 -> 0.83210563
U33: =AA33 -> Previsão de baixa populacional da ONU (0 - 1,4 Gp) | W33: =W28 -> 1400 | AA33: =CONCATENATE(A21," (0 - ",W33/1000," Gp)") -> Previsão de baixa populacional da ONU (0 - 1,4 Gp) | AK33: =K21/$W33 -> 0.97499808 | AL33: =L21/$W33 -> 0.97434565 | AM33: =M21/$W33 -> 0.96414347 | AN33: =N21/$W33 -> 0.94826874 | AO33: =O21/$W33 -> 0.92577555 | AP33: =P21/$W33 -> 0.89550247 | AQ33: =Q21/$W33 -> 0.85770429 | AR33: =R21/$W33 -> 0.8137691
U34: =AA34 -> Nascimentos: Previsão baixa da ONU (0 - 30 milhões/ano) | W34: =W29 -> 30 | AA34: =CONCATENATE(A22," (0 - ",W34," Mp / yr)") -> Nascimentos: Previsão baixa da ONU (0 - 30 milhões/ano) | AJ34: =J22/$W34 -> 0.45435905 | AK34: =K22/$W34 -> 0.36625625 | AL34: =L22/$W34 -> 0.31005924 | AM34: =M22/$W34 -> 0.29762131 | AN34: =N22/$W34 -> 0.28290283 | AO34: =O22/$W34 -> 0.259543 | AP34: =P22/$W34 -> 0.23325775 | AQ34: =Q22/$W34 -> 0.21061884 | AR34: =R22/$W34 -> 0.19385837
U35: =AA35 -> Mortes: Previsão baixa da ONU (0 - 20 milhões/ano) | W35: =W30 -> 20 | AA35: =CONCATENATE(A23," (0 - ",W35," Mp / yr)") -> Mortes: Previsão baixa da ONU (0 - 20 milhões/ano) | AJ35: =J23/$W35 -> 0.50664595 | AK35: =K23/$W35 -> 0.54275325 | AL35: =L23/$W35 -> 0.59269988 | AM35: =M23/$W35 -> 0.65419137 | AN35: =N23/$W35 -> 0.72479963 | AO35: =O23/$W35 -> 0.7985822 | AP35: =P23/$W35 -> 0.86453997 | AQ35: =Q23/$W35 -> 0.91647281 | AR35: =R23/$W35 -> 0.94799859
U36: =AA36 -> Baixa taxa de natalidade da ONU (0 - 4% / ano) | W36: =W31 -> 4 | AA36: =CONCATENATE(A24," (0 - ",W36," % / yr)") -> Baixa taxa de natalidade da ONU (0 - 4% / ano) | AJ36: =J24/$W36 -> 0.25262154 | AK36: =K24/$W36 -> 0.20124009 | AL36: =L24/$W36 -> 0.17047663 | AM36: =M24/$W36 -> 0.16536956 | AN36: =N24/$W36 -> 0.15982293 | AO36: =O24/$W36 -> 0.15018856 | AP36: =P24/$W36 -> 0.13954122 | AQ36: =Q24/$W36 -> 0.13155061 | AR36: =R24/$W36 -> 0.12761937
U37: =AA37 -> Baixa taxa de mortalidade da ONU (0 - 2% / ano) | W37: =W32 -> 2 | AA37: =CONCATENATE(A25," (0 - ",W37," % / yr)") -> Baixa taxa de mortalidade da ONU (0 - 2% / ano) | AJ37: =J25/$W37 -> 0.37559043 | AK37: =K25/$W37 -> 0.39762221 | AL37: =L25/$W37 -> 0.43450397 | AM37: =M25/$W37 -> 0.48465769 | AN37: =N25/$W37 -> 0.54595707 | AO37: =O25/$W37 -> 0.61614919 | AP37: =P25/$W37 -> 0.68958889 | AQ37: =Q25/$W37 -> 0.76322742 | AR37: =R25/$W37 -> 0.83210563
U38: =AA38 -> População da China: Sua previsão (0 - 1,4 Gp) | W38: 1400 | AA38: =CONCATENATE(A9," Your forecast (0 - ",W38/1000," Gp)") -> População da China: Sua previsão (0 - 1,4 Gp) | AK38: =K17/$W38 -> 0.97551 | AL38: =L17/$W38 -> 0.97812732 | AM38: =M17/$W38 -> 0.97242348 | AN38: =N17/$W38 -> 0.95959093 | AO38: =O17/$W38 -> 0.93881215 | AP38: =P17/$W38 -> 0.91064533 | AQ38: =Q17/$W38 -> 0.87587715 | AR38: =R17/$W38 -> 0.83525722
U39: =AA39 -> Nascimentos, China Sua previsão (0 - 30 milhões/ano) | W39: 30 | AA39: =CONCATENATE(A10," Your forecast (0 - ",W39," Mp / yr)") -> Nascimentos, China Sua previsão (0 - 30 milhões/ano) | AJ39: =J18/$W39 -> 0.449644 | AK39: =K18/$W39 -> 0.37921325 | AL39: =L18/$W39 -> 0.33549767 | AM39: =M18/$W39 -> 0.31130517 | AN39: =N18/$W39 -> 0.2852544 | AO39: =O18/$W39 -> 0.26619706 | AP39: =P18/$W39 -> 0.24988108 | AQ39: =Q18/$W39 -> 0.23232933 | AR39: =R18/$W39 -> 0.21391494
U40: =AA40 -> Mortes, China Sua previsão (0 - 20 milhões/ano) | W40: 20 | AA40: =CONCATENATE(A11," Your forecast (0 - ",W40," Mp / yr)") -> Mortes, China Sua previsão (0 - 20 milhões/ano) | AJ40: =J19/$W40 -> 0.50664595 | AK40: =K19/$W40 -> 0.53217746 | AL40: =L19/$W40 -> 0.58310028 | AM40: =M19/$W40 -> 0.64661333 | AN40: =N19/$W40 -> 0.71878457 | AO40: =O19/$W40 -> 0.79363114 | AP40: =P19/$W40 -> 0.86157607 | AQ40: =Q19/$W40 -> 0.91717302 | AR40: =R19/$W40 -> 0.95357051
...

Sheet  OCDE
A1: =SumWorld!A1 -> Prezado(a) usuário(a): Esta é a versão de 7 de novembro de 2014, às 11h, da planilha de 2052 de Ulrich Goluke (2052@blue-way.net)
A2: =SumWorld!A2 -> Prezado(a) usuário(a): O lado esquerdo desta planilha contém os dados numéricos e os gráficos que você também encontra no livro de 2052. | U2: =SumWorld!U2 -> Prezado(a) usuário(a): Os cálculos nesta parte à direita da planilha garantem o dimensionamento correto dos gráficos.
U3: =SumWorld!U3 -> Contém também a fonte dos dados históricos.
I4: Código de cores | J4: Dados históricos | M4: Sua previsão
A5: EUA sem OCDE | J5: Previsão de Randers | M5: Calculado a partir da sua previsão.
J6: Valores calculados | M6: Suas próprias células de referência
A7: =CONCATENATE("Graph 1. Population - ",A5," 1970 to 2050") -> Gráfico 1. População - EUA (excluindo os países da OCDE) de 1970 a 2050
B8: 1970 | C8: 1975 | D8: 1980 | E8: 1985 | F8: 1990 | G8: 1995 | H8: 2000 | I8: 2005 | J8: 2010 | K8: 2015 | L8: 2020 | M8: 2025 | N8: 2030 | O8: 2035 | P8: 2040 | Q8: 2045 | R8: 2050 | S8: Unidades
A9: População, EUA sem a OCDE | B9: 595.37423 | C9: 621.51645 | D9: 641.18903 | E9: 657.80781 | F9: 673.72223 | G9: 691.03659 | H9: 702.81364 | I9: 719.52914 | J9: 737.13711 | K9: =J9+(J10-J11)*5 -> 741.75302 | L9: =K9+(K10-K11)*5 -> 740.76498 | M9: =L9+(L10-L11)*5 -> 734.7481 | N9: =M9+(M10-M11)*5 -> 725.44947 | O9: =N9+(N10-N11)*5 -> 714.16577 | P9: =O9+(O10-O11)*5 -> 700.45645 | Q9: =P9+(P10-P11)*5 -> 683.7935 | R9: =Q9+(Q10-Q11)*5 -> 663.89229 | S9: Deputado | U9: A tabela original foi baixada de http://esa.un.org/unpd/wpp/Excel-Data/DB03_Population_ByAgeSex_Quinquennial/WPP2010_DB3_F1_POPULATION_BY_AGE_BOTH_SEXES.XLS
A10: Nascimentos, EUA sem a OCDE | B10: 10.403606 | C10: 9.4395844 | D10: 8.9810776 | E10: 8.5176402 | F10: 8.1983918 | G10: 7.7033278 | H10: 7.4231628 | I10: 7.6935372 | J10: =J9*J12/100 -> 7.7399397 | K10: =K9*K12/100 -> 7.0466537 | L10: =L9*L12/100 -> 6.4446553 | M10: =M9*M12/100 -> 6.1718841 | N10: =N9*N12/100 -> 6.1663205 | O10: =O9*O12/100 -> 6.070409 | P10: =P9*P12/100 -> 5.8137886 | Q10: =Q9*Q12/100 -> 5.4019686 | R10: =R9*R12/100 -> 5.1119706 | S10: Mp/ano | U10: Último acesso em 11 de abril de 2012
A11: Mortes, EUA sem a OCDE | B11: 5.810134 | C11: 5.8885266 | D11: 5.9735352 | E11: 6.0339716 | F11: 6.1572358 | G11: 6.2603932 | H11: 6.2499424 | I11: 6.4179822 | J11: =J9*J13/100 -> 6.8167586 | K11: =K9*K13/100 -> 7.2442609 | L11: =L9*L13/100 -> 7.6480311 | M11: =M9*M13/100 -> 8.0316098 | N11: =N9*N13/100 -> 8.4230622 | O11: =O9*O13/100 -> 8.8122716 | P11: =P9*P13/100 -> 9.1463796 | Q11: =Q9*Q13/100 -> 9.3822097 | R11: =R9*R13/100 -> 9.4833785 | S11: Mp/ano | U11: Para valores futuros, foi utilizada a variante BAIXA.
A12: taxa bruta de natalidade | B12: =B10/B9*100 -> 1.7474062 | C12: =C10/C9*100 -> 1.5187988 | D12: =D10/D9*100 -> 1.4006911 | E12: =E10/E9*100 -> 1.2948524 | F12: =F10/F9*100 -> 1.2168801 | G12: =G10/G9*100 -> 1.1147496 | H12: =H10/H9*100 -> 1.0562064 | I12: =I10/I9*100 -> 1.0692461 | J12: 1.05 | K12: 0.95 | L12: 0.87 | M12: 0.84 | N12: 0.85 | O12: 0.85 | P12: 0.83 | Q12: 0.79 | R12: 0.77 | S12: % por ano
A13: taxa bruta de mortalidade | B13: =B11/B9*100 -> 0.97587933 | C13: =C11/C9*100 -> 0.94744502 | D13: =D11/D9*100 -> 0.93163402 | E13: =E11/E9*100 -> 0.91728489 | F13: =F11/F9*100 -> 0.91391311 | G13: =G11/G9*100 -> 0.90594237 | H13: =H11/H9*100 -> 0.88927448 | I13: =I11/I9*100 -> 0.89196973 | J13: 0.92476128 | K13: 0.97664057 | L13: 1.0324504 | M13: 1.0931107 | N13: 1.1610819 | O13: 1.2339252 | P13: 1.3057742 | Q13: 1.3720823 | R13: 1.4284514 | S13: % por ano
A14: Sua previsão
G15: taxa bruta de natalidade | I15: Sua previsão | J15: =J12 -> 1.05 | K15: =K12*0.98 -> 0.931 | L15: =L12*0.98 -> 0.8526 | M15: =M12*0.98 -> 0.8232 | N15: =N12*0.98 -> 0.833 | O15: =O12*0.98 -> 0.833 | P15: =P12*0.98 -> 0.8134 | Q15: =Q12*0.98 -> 0.7742 | R15: =R12*0.98 -> 0.7546 | S15: % por ano
G16: taxa bruta de mortalidade | I16: Sua previsão | J16: =J13 -> 0.92476128 | K16: =K13*0.98 -> 0.95710775 | L16: =L13*0.98 -> 1.0118014 | M16: =M13*0.98 -> 1.0712484 | N16: =N13*0.98 -> 1.1378602 | O16: =O13*0.98 -> 1.2092467 | P16: =P13*0.98 -> 1.2796587 | Q16: =Q13*0.98 -> 1.3446407 | R16: =R13*0.98 -> 1.3998823 | S16: % por ano
I17: População, EUA sem a OCDE | K17: =J9+(J18-J19)*5 -> 741.75302 | L17: =K17+(K18-K19)*5 -> 740.78474 | M17: =L17+(L18-L19)*5 -> 734.88804 | N17: =M17+(M18-M19)*5 -> 725.77365 | O17: =N17+(N18-N19)*5 -> 714.71068 | P17: =O17+(O18-O19)*5 -> 701.2653 | Q17: =P17+(P18-P19)*5 -> 684.91675 | R17: =Q17+(Q18-Q19)*5 -> 665.38153 | S17: Deputado
I18: Nascimentos, EUA sem a OCDE | J18: =J9*J15/100 -> 7.7399397 | K18: =K17*K15/100 -> 6.9057206 | L18: =L17*L15/100 -> 6.3159307 | M18: =M17*M15/100 -> 6.0495984 | N18: =N17*N15/100 -> 6.0456945 | O18: =O17*O15/100 -> 5.9535399 | P18: =P17*P15/100 -> 5.7040919 | Q18: =Q17*Q15/100 -> 5.3026254 | R18: =R17*R15/100 -> 5.020969 | S18: Mp/ano
I19: Mortes, EUA sem a OCDE | J19: =J9*J16/100 -> 6.8167586 | K19: =K17*K16/100 -> 7.0993756 | L19: =L17*L16/100 -> 7.4952704 | M19: =M17*M16/100 -> 7.8724767 | N19: =N17*N16/100 -> 8.2582897 | O19: =O17*O16/100 -> 8.6426154 | P19: =P17*P16/100 -> 8.9738025 | Q19: =Q17*Q16/100 -> 9.2096692 | R19: =R17*R16/100 -> 9.3145584 | S19: Mp/ano
A20: Apenas para fins informativos
A21: Previsão baixa da população da ONU | K21: 743.10788 | L21: 743.32335 | M21: 738.92257 | N21: 732.14571 | O21: 722.7466 | P21: 710.61069 | Q21: 695.28118 | R21: 676.74758 | S21: Deputado
A22: Nascimentos: baixa previsão da ONU | J22: 6.5982612 | K22: 5.9354542 | L22: 5.492522 | M22: 5.4833162 | N22: 5.462532 | O22: 5.3923714 | P22: 5.1640334 | Q22: 4.8247416 | R22: 4.5436994 | S22: Mp/ano
A23: Mortes: previsão baixa da ONU | J23: 6.8167586 | K23: 7.257493 | L23: 7.674445 | M23: 8.0772414 | N23: 8.500811 | O23: 8.9181526 | P23: 9.278971 | Q23: 9.5398302 | R23: 9.66701 | S23: Mp/ano
A24: Baixa taxa de natalidade da ONU | J24: =J22/J9*100 -> 0.89511993 | K24: =K22/K21*100 -> 0.79873385 | L24: =L22/L21*100 -> 0.73891423 | M24: =M22/M21*100 -> 0.74206911 | N24: =N22/N21*100 -> 0.74609903 | O24: =O22/O21*100 -> 0.74609433 | P24: =P22/P21*100 -> 0.72670359 | Q24: =Q22/Q21*100 -> 0.69392668 | R24: =R22/R21*100 -> 0.67140239 | S24: % por ano
A25: Baixa taxa de mortalidade da ONU | J25: =J23/J9*100 -> 0.92476128 | K25: =K23/K21*100 -> 0.97664057 | L25: =L23/L21*100 -> 1.0324504 | M25: =M23/M21*100 -> 1.0931107 | N25: =N23/N21*100 -> 1.1610819 | O25: =O23/O21*100 -> 1.2339252 | P25: =P23/P21*100 -> 1.3057742 | Q25: =Q23/Q21*100 -> 1.3720823 | R25: =R23/R21*100 -> 1.4284514 | S25: % por ano | X25: Prezado(a) usuário(a): Utilize a tabela amarela abaixo para definir o valor máximo nos eixos verticais do gráfico.
E26: Para taxas: o valor inserido no ano n é o valor médio anual entre n e n+5. | V26: Valor máximo no eixo vertical | AA26: Cálculos realizados para ajustar todas as variáveis para valores entre 0 e 1.
U27: Para o gráfico à esquerda, nomes das variáveis (unidade) | V27: nos gráficos originais de Randers | W27: Na sua previsão | AB27: 1970 | AC27: 1975 | AD27: 1980 | AE27: 1985 | AF27: 1990 | AG27: 1995 | AH27: 2000 | AI27: 2005 | AJ27: 2010 | AK27: 2015 | AL27: 2020 | AM27: 2025 | AN27: 2030 | AO27: 2035 | AP27: 2040 | AQ27: 2045 | AR27: 2050
U28: =AA28 -> População, OCDE-excluindo EUA (0 - 0,75 Gp) | V28: 750 | W28: =W38 -> 750 | AA28: =CONCATENATE(A9," (0 - ",W28/1000," Gp)") -> População, OCDE-excluindo EUA (0 - 0,75 Gp) | AB28: =B9/$W28 -> 0.7938323 | AC28: =C9/$W28 -> 0.8286886 | AD28: =D9/$W28 -> 0.85491871 | AE28: =E9/$W28 -> 0.87707707 | AF28: =F9/$W28 -> 0.89829631 | AG28: =G9/$W28 -> 0.92138212 | AH28: =H9/$W28 -> 0.93708486 | AI28: =I9/$W28 -> 0.95937219 | ... AR28: =R9/$W28 -> 0.88518972
U29: =AA29 -> Nascimentos, países da OCDE excluindo os EUA (0 - 12 milhões/ano) | V29: 12 | W29: =W39 -> 12 | AA29: =CONCATENATE(A10," (0 - ",W29," Mp / yr)") -> Nascimentos, países da OCDE excluindo os EUA (0 - 12 milhões/ano) | AB29: =B10/$W29 -> 0.86696717 | AC29: =C10/$W29 -> 0.78663203 | AD29: =D10/$W29 -> 0.74842313 | AE29: =E10/$W29 -> 0.70980335 | AF29: =F10/$W29 -> 0.68319932 | AG29: =G10/$W29 -> 0.64194398 | AH29: =H10/$W29 -> 0.6185969 | AI29: =I10/$W29 -> 0.6411281 | ... AR29: =R10/$W29 -> 0.42599755
U30: =AA30 -> Mortes, países da OCDE excluindo os EUA (0 - 10 milhões/ano) | V30: 10 | W30: =W40 -> 10 | AA30: =CONCATENATE(A11," (0 - ",W30," Mp / yr)") -> Mortes, países da OCDE excluindo os EUA (0 - 10 milhões/ano) | AB30: =B11/$W30 -> 0.5810134 | AC30: =C11/$W30 -> 0.58885266 | AD30: =D11/$W30 -> 0.59735352 | AE30: =E11/$W30 -> 0.60339716 | AF30: =F11/$W30 -> 0.61572358 | AG30: =G11/$W30 -> 0.62603932 | AH30: =H11/$W30 -> 0.62499424 | AI30: =I11/$W30 -> 0.64179822 | ... AR30: =R11/$W30 -> 0.94833785
U31: =AA31 -> Taxa bruta de natalidade (0 - 2 % / ano) | V31: 2 | W31: =W41 -> 2 | AA31: =CONCATENATE(A12," (0 - ",W31," % / yr)") -> Taxa bruta de natalidade (0 - 2 % / ano) | AB31: =B12/$W31 -> 0.87370309 | AC31: =C12/$W31 -> 0.7593994 | AD31: =D12/$W31 -> 0.70034554 | AE31: =E12/$W31 -> 0.6474262 | AF31: =F12/$W31 -> 0.60844005 | AG31: =G12/$W31 -> 0.55737482 | AH31: =H12/$W31 -> 0.52810321 | AI31: =I12/$W31 -> 0.53462304 | ... AR31: =R12/$W31 -> 0.385
U32: =AA32 -> Taxa bruta de mortalidade (0 - 2 % / ano) | V32: 2 | W32: =W42 -> 2 | AA32: =CONCATENATE(A13," (0 - ",W32," % / yr)") -> Taxa bruta de mortalidade (0 - 2 % / ano) | AB32: =B13/$W32 -> 0.48793966 | AC32: =C13/$W32 -> 0.47372251 | AD32: =D13/$W32 -> 0.46581701 | AE32: =E13/$W32 -> 0.45864244 | AF32: =F13/$W32 -> 0.45695655 | AG32: =G13/$W32 -> 0.45297118 | AH32: =H13/$W32 -> 0.44463724 | AI32: =I13/$W32 -> 0.44598487 | ... AR32: =R13/$W32 -> 0.71422568
U33: =AA33 -> Previsão de baixa população da ONU (0 - 0,75 Gp) | W33: =W28 -> 750 | AA33: =CONCATENATE(A21," (0 - ",W33/1000," Gp)") -> Previsão de baixa população da ONU (0 - 0,75 Gp) | AK33: =K21/$W33 -> 0.99081051 | AL33: =L21/$W33 -> 0.9910978 | AM33: =M21/$W33 -> 0.9852301 | AN33: =N21/$W33 -> 0.97619428 | AO33: =O21/$W33 -> 0.96366213 | AP33: =P21/$W33 -> 0.94748091 | AQ33: =Q21/$W33 -> 0.92704158 | AR33: =R21/$W33 -> 0.90233011
U34: =AA34 -> Nascimentos: Previsão baixa da ONU (0 - 12 milhões/ano) | W34: =W29 -> 12 | AA34: =CONCATENATE(A22," (0 - ",W34," Mp / yr)") -> Nascimentos: Previsão baixa da ONU (0 - 12 milhões/ano) | AJ34: =J22/$W34 -> 0.5498551 | AK34: =K22/$W34 -> 0.49462118 | AL34: =L22/$W34 -> 0.45771017 | AM34: =M22/$W34 -> 0.45694302 | AN34: =N22/$W34 -> 0.455211 | AO34: =O22/$W34 -> 0.44936428 | AP34: =P22/$W34 -> 0.43033612 | AQ34: =Q22/$W34 -> 0.4020618 | AR34: =R22/$W34 -> 0.37864162
U35: =AA35 -> Mortes: Previsão baixa da ONU (0 - 10 milhões/ano) | W35: =W30 -> 10 | AA35: =CONCATENATE(A23," (0 - ",W35," Mp / yr)") -> Mortes: Previsão baixa da ONU (0 - 10 milhões/ano) | AJ35: =J23/$W35 -> 0.68167586 | AK35: =K23/$W35 -> 0.7257493 | AL35: =L23/$W35 -> 0.7674445 | AM35: =M23/$W35 -> 0.80772414 | AN35: =N23/$W35 -> 0.8500811 | AO35: =O23/$W35 -> 0.89181526 | AP35: =P23/$W35 -> 0.9278971 | AQ35: =Q23/$W35 -> 0.95398302 | AR35: =R23/$W35 -> 0.966701
U36: =AA36 -> Baixa taxa de natalidade da ONU (0 - 2% / ano) | W36: =W31 -> 2 | AA36: =CONCATENATE(A24," (0 - ",W36," % / yr)") -> Baixa taxa de natalidade da ONU (0 - 2% / ano) | AJ36: =J24/$W36 -> 0.44755996 | AK36: =K24/$W36 -> 0.39936693 | AL36: =L24/$W36 -> 0.36945712 | AM36: =M24/$W36 -> 0.37103456 | AN36: =N24/$W36 -> 0.37304951 | AO36: =O24/$W36 -> 0.37304717 | AP36: =P24/$W36 -> 0.3633518 | AQ36: =Q24/$W36 -> 0.34696334 | AR36: =R24/$W36 -> 0.33570119
U37: =AA37 -> Baixa taxa de mortalidade da ONU (0 - 2% / ano) | W37: =W32 -> 2 | AA37: =CONCATENATE(A25," (0 - ",W37," % / yr)") -> Baixa taxa de mortalidade da ONU (0 - 2% / ano) | AJ37: =J25/$W37 -> 0.46238064 | AK37: =K25/$W37 -> 0.48832028 | AL37: =L25/$W37 -> 0.51622521 | AM37: =M25/$W37 -> 0.54655533 | AN37: =N25/$W37 -> 0.58054093 | AO37: =O25/$W37 -> 0.61696261 | AP37: =P25/$W37 -> 0.6528871 | AQ37: =Q25/$W37 -> 0.68604116 | AR37: =R25/$W37 -> 0.71422568
U38: =AA38 -> População, OCDE excluindo EUA Sua previsão (0 - 0,75 Gp) | W38: 750 | AA38: =CONCATENATE(A9," Your forecast (0 - ",W38/1000," Gp)") -> População, OCDE excluindo EUA Sua previsão (0 - 0,75 Gp) | AK38: =K17/$W38 -> 0.98900402 | AL38: =L17/$W38 -> 0.98771299 | AM38: =M17/$W38 -> 0.97985072 | AN38: =N17/$W38 -> 0.9676982 | AO38: =O17/$W38 -> 0.95294757 | AP38: =P17/$W38 -> 0.9350204 | AQ38: =Q17/$W38 -> 0.91322233 | AR38: =R17/$W38 -> 0.88717537
U39: =AA39 -> Nascimentos, EUA (excluindo países da OCDE) Sua previsão (0 - 12 milhões/ano) | W39: 12 | AA39: =CONCATENATE(A10," Your forecast (0 - ",W39," Mp / yr)") -> Nascimentos, EUA (excluindo países da OCDE) Sua previsão (0 - 12 milhões/ano) | AJ39: =J18/$W39 -> 0.64499497 | AK39: =K18/$W39 -> 0.57547672 | AL39: =L18/$W39 -> 0.52632756 | AM39: =M18/$W39 -> 0.5041332 | AN39: =N18/$W39 -> 0.50380788 | AO39: =O18/$W39 -> 0.49612833 | AP39: =P18/$W39 -> 0.47534099 | AQ39: =Q18/$W39 -> 0.44188545 | AR39: =R18/$W39 -> 0.41841408
U40: =AA40 -> Mortes, EUA sem a OCDE: Sua previsão (0 - 10 milhões/ano) | W40: 10 | AA40: =CONCATENATE(A11," Your forecast (0 - ",W40," Mp / yr)") -> Mortes, EUA sem a OCDE: Sua previsão (0 - 10 milhões/ano) | AJ40: =J19/$W40 -> 0.68167586 | AK40: =K19/$W40 -> 0.70993756 | AL40: =L19/$W40 -> 0.74952704 | AM40: =M19/$W40 -> 0.78724767 | AN40: =N19/$W40 -> 0.82582897 | AO40: =O19/$W40 -> 0.86426154 | AP40: =P19/$W40 -> 0.89738025 | AQ40: =Q19/$W40 -> 0.92096692 | AR40: =R19/$W40 -> 0.93145584
...

Sheet  BRISE
A1: =SumWorld!A1 -> Prezado(a) usuário(a): Esta é a versão de 7 de novembro de 2014, às 11h, da planilha de 2052 de Ulrich Goluke (2052@blue-way.net)
A2: =SumWorld!A2 -> Prezado(a) usuário(a): O lado esquerdo desta planilha contém os dados numéricos e os gráficos que você também encontra no livro de 2052. | U2: =SumWorld!U2 -> Prezado(a) usuário(a): Os cálculos nesta parte à direita da planilha garantem o dimensionamento correto dos gráficos.
U3: =SumWorld!U3 -> Contém também a fonte dos dados históricos.
I4: Código de cores | J4: Dados históricos | M4: Sua previsão
A5: BRISE | J5: Previsão de Randers | M5: Calculado a partir da sua previsão.
J6: Valores calculados | M6: Suas próprias células de referência
A7: =CONCATENATE("Graph 1. Population - ",A5," 1970 to 2050") -> Gráfico 1. População - BRISE 1970 a 2050
B8: 1970 | C8: 1975 | D8: 1980 | E8: 1985 | F8: 1990 | G8: 1995 | H8: 2000 | I8: 2005 | J8: 2010 | K8: 2015 | L8: 2020 | M8: 2025 | N8: 2030 | O8: 2035 | P8: 2040 | Q8: 2045 | R8: 2050 | S8: Unidades
A9: População, BRISE | B9: 1206.7983 | C9: 1344.3765 | D9: 1496.2993 | E9: 1661.9837 | F9: 1830.4117 | G9: 1986.892 | H9: 2134.2957 | I9: 2275.4979 | J9: 2411.931 | K9: =J9+(J10-J11)*5 -> 2521.9526 | L9: =K9+(K10-K11)*5 -> 2609.3336 | M9: =L9+(L10-L11)*5 -> 2678.4969 | N9: =M9+(M10-M11)*5 -> 2724.7967 | O9: =N9+(N10-N11)*5 -> 2751.4596 | P9: =O9+(O10-O11)*5 -> 2755.7626 | Q9: =P9+(P10-P11)*5 -> 2735.925 | R9: =Q9+(Q10-Q11)*5 -> 2695.2035 | S9: Deputado | U9: A tabela original foi baixada de http://esa.un.org/unpd/wpp/Excel-Data/DB03_Population_ByAgeSex_Quinquennial/WPP2010_DB3_F1_POPULATION_BY_AGE_BOTH_SEXES.XLS
A10: Nascimentos, BRISE | B10: 42.291032 | C10: 45.193874 | D10: 47.81578 | E10: 48.598529 | F10: 47.412844 | G10: 45.748274 | H10: 45.302026 | I10: 45.13372 | J10: =J9*J12/100 -> 41.002828 | K10: =K9*K12/100 -> 37.829289 | L10: =L9*L12/100 -> 35.226004 | M10: =M9*M12/100 -> 32.141963 | N10: =N9*N12/100 -> 29.972764 | O10: =O9*O12/100 -> 27.514596 | P10: =P9*P12/100 -> 24.801864 | Q10: =Q9*Q12/100 -> 22.708178 | R10: =R9*R12/100 -> 20.214026 | S10: Mp/ano | U10: Último acesso em 11 de abril de 2012
A11: Mortes, BRISE | B11: 16.383585 | C11: 16.239845 | D11: 16.691314 | E11: 16.670833 | F11: 17.284284 | G11: 17.795354 | H11: 18.485538 | I11: 18.863748 | J11: =J9*J13/100 -> 18.998511 | K11: =K9*K13/100 -> 20.353093 | L11: =L9*L13/100 -> 21.393342 | M11: =M9*M13/100 -> 22.882007 | N11: =N9*N13/100 -> 24.640181 | O11: =O9*O13/100 -> 26.653993 | P11: =P9*P13/100 -> 28.769385 | Q11: =Q9*Q13/100 -> 30.852479 | R11: =R9*R13/100 -> 32.847473 | S11: Mp/ano | U11: Para valores futuros, foi utilizada a variante BAIXA.
A12: taxa bruta de natalidade | B12: =B10/B9*100 -> 3.5043992 | C12: =C10/C9*100 -> 3.3616978 | D12: =D10/D9*100 -> 3.1956026 | E12: =E10/E9*100 -> 2.9241279 | F12: =F10/F9*100 -> 2.5902831 | G12: =G10/G9*100 -> 2.3025043 | H12: =H10/H9*100 -> 2.1225749 | I12: =I10/I9*100 -> 1.9834657 | J12: 1.7 | K12: 1.5 | L12: 1.35 | M12: 1.2 | N12: 1.1 | O12: 1 | P12: 0.9 | Q12: 0.83 | R12: 0.75 | S12: % por ano
A13: taxa bruta de mortalidade | B13: =B11/B9*100 -> 1.3576075 | C13: =C11/C9*100 -> 1.2079835 | D13: =D11/D9*100 -> 1.1155064 | E13: =E11/E9*100 -> 1.0030684 | F13: =F11/F9*100 -> 0.94428399 | G13: =G11/G9*100 -> 0.89563768 | H13: =H11/H9*100 -> 0.86611888 | I13: =I11/I9*100 -> 0.82899431 | J13: 0.78768882 | K13: 0.80703709 | L13: 0.81987762 | M13: 0.85428536 | N13: 0.9042943 | O13: 0.96872193 | P13: 1.0439718 | Q13: 1.12768 | R13: 1.2187381 | S13: % por ano
A14: Sua previsão
G15: taxa bruta de natalidade | I15: Sua previsão | J15: =J12 -> 1.7 | K15: =K12*0.98 -> 1.47 | L15: =L12*0.98 -> 1.323 | M15: =M12*0.98 -> 1.176 | N15: =N12*0.98 -> 1.078 | O15: =O12*0.98 -> 0.98 | P15: =P12*0.98 -> 0.882 | Q15: =Q12*0.98 -> 0.8134 | R15: =R12*0.98 -> 0.735 | S15: % por ano
G16: taxa bruta de mortalidade | I16: Sua previsão | J16: =J13 -> 0.78768882 | K16: =K13*0.98 -> 0.79089635 | L16: =L13*0.98 -> 0.80348007 | M16: =M13*0.98 -> 0.83719965 | N16: =N13*0.98 -> 0.88620842 | O16: =O13*0.98 -> 0.94934749 | P16: =P13*0.98 -> 1.0230924 | Q16: =Q13*0.98 -> 1.1051264 | R16: =R13*0.98 -> 1.1943634 | S16: % por ano
I17: População, BRISE | K17: =J9+(J18-J19)*5 -> 2521.9526 | L17: =K17+(K18-K19)*5 -> 2607.586 | M17: =L17+(L18-L19)*5 -> 2675.3206 | N17: =M17+(M18-M19)*5 -> 2720.6406 | O17: =N17+(N18-N19)*5 -> 2746.7304 | P17: =O17+(O18-O19)*5 -> 2750.9401 | Q17: =P17+(P18-P19)*5 -> 2731.5333 | R17: =Q17+(Q18-Q19)*5 -> 2691.6903 | S17: Deputado
I18: Nascimentos, BRISE | J18: =J9*J15/100 -> 41.002828 | K18: =K17*K15/100 -> 37.072704 | L18: =L17*L15/100 -> 34.498363 | M18: =M17*M15/100 -> 31.461771 | N18: =N17*N15/100 -> 29.328506 | O18: =O17*O15/100 -> 26.917958 | P18: =P17*P15/100 -> 24.263292 | Q18: =Q17*Q15/100 -> 22.218292 | R18: =R17*R15/100 -> 19.783923 | S18: Mp/ano
I19: Mortes, BRISE | J19: =J9*J16/100 -> 18.998511 | K19: =K17*K16/100 -> 19.946031 | L19: =L17*L16/100 -> 20.951434 | M19: =M17*M16/100 -> 22.397775 | N19: =N17*N16/100 -> 24.110546 | O19: =O17*O16/100 -> 26.076016 | P19: =P17*P16/100 -> 28.144658 | Q19: =Q17*Q16/100 -> 30.186896 | R19: =R17*R16/100 -> 32.148562 | S19: Mp/ano
A20: Apenas para fins informativos
A21: Previsão baixa da população da ONU | K21: 2429.8168 | L21: 2507.2307 | M21: 2561.2722 | N21: 2599.8554 | O21: 2620.2185 | P21: 2619.072 | Q21: 2595.2994 | R21: 2550.3438 | S21: Deputado
A22: Nascimentos: baixa previsão da ONU | J22: 39.199335 | K22: 34.579519 | L22: 30.792424 | M22: 29.056215 | N22: 27.088792 | O22: 24.701367 | P22: 22.154044 | Q22: 19.860383 | R22: 18.045262 | S22: Mp/ano
A23: Mortes: previsão baixa da ONU | J23: 18.998511 | K23: 19.609523 | L23: 20.556223 | M23: 21.880573 | N23: 23.510344 | O23: 25.382631 | P23: 27.342373 | Q23: 29.266672 | R23: 31.082012 | S23: Mp/ano
A24: Baixa taxa de natalidade da ONU | J24: =J22/J9*100 -> 1.6252262 | K24: =K22/K21*100 -> 1.4231328 | L24: =L22/L21*100 -> 1.2281448 | M24: =M22/M21*100 -> 1.1344446 | N24: =N22/N21*100 -> 1.0419345 | O24: =O22/O21*100 -> 0.94272165 | P24: =P22/P21*100 -> 0.8458738 | Q24: =Q22/Q21*100 -> 0.76524438 | R24: =R22/R21*100 -> 0.70756192 | S24: % por ano
A25: Baixa taxa de mortalidade da ONU | J25: =J23/J9*100 -> 0.78768882 | K25: =K23/K21*100 -> 0.80703709 | L25: =L23/L21*100 -> 0.81987762 | M25: =M23/M21*100 -> 0.85428536 | N25: =N23/N21*100 -> 0.9042943 | O25: =O23/O21*100 -> 0.96872193 | P25: =P23/P21*100 -> 1.0439718 | Q25: =Q23/Q21*100 -> 1.12768 | R25: =R23/R21*100 -> 1.2187381 | S25: % por ano | X25: Prezado(a) usuário(a): Utilize a tabela amarela abaixo para definir o valor máximo nos eixos verticais do gráfico.
E26: Para taxas: o valor inserido no ano n é o valor médio anual entre n e n+5. | V26: Valor máximo no eixo vertical | AA26: Cálculos realizados para ajustar todas as variáveis para valores entre 0 e 1.
U27: Para o gráfico à esquerda, nomes das variáveis (unidade) | V27: nos gráficos originais de Randers | W27: Na sua previsão | AB27: 1970 | AC27: 1975 | AD27: 1980 | AE27: 1985 | AF27: 1990 | AG27: 1995 | AH27: 2000 | AI27: 2005 | AJ27: 2010 | AK27: 2015 | AL27: 2020 | AM27: 2025 | AN27: 2030 | AO27: 2035 | AP27: 2040 | AQ27: 2045 | AR27: 2050
U28: =AA28 -> População, BRISE (0 - 3 Gp) | V28: 3000 | W28: =W38 -> 3000 | AA28: =CONCATENATE(A9," (0 - ",W28/1000," Gp)") -> População, BRISE (0 - 3 Gp) | AB28: =B9/$W28 -> 0.40226611 | AC28: =C9/$W28 -> 0.44812549 | AD28: =D9/$W28 -> 0.49876645 | AE28: =E9/$W28 -> 0.55399457 | AF28: =F9/$W28 -> 0.61013723 | AG28: =G9/$W28 -> 0.66229734 | AH28: =H9/$W28 -> 0.7114319 | AI28: =I9/$W28 -> 0.75849929 | ... AR28: =R9/$W28 -> 0.89840117
U29: =AA29 -> Nascimentos, BRISE (0 - 50 milhões/ano) | V29: 50 | W29: =W39 -> 50 | AA29: =CONCATENATE(A10," (0 - ",W29," Mp / yr)") -> Nascimentos, BRISE (0 - 50 milhões/ano) | AB29: =B10/$W29 -> 0.84582063 | AC29: =C10/$W29 -> 0.90387748 | AD29: =D10/$W29 -> 0.95631561 | AE29: =E10/$W29 -> 0.97197058 | AF29: =F10/$W29 -> 0.94825688 | AG29: =G10/$W29 -> 0.91496548 | AH29: =H10/$W29 -> 0.90604052 | AI29: =I10/$W29 -> 0.90267439 | ... AR29: =R10/$W29 -> 0.40428053
U30: =AA30 -> Mortes, BRISE (0 - 35 milhões/ano) | V30: 35 | W30: =W40 -> 35 | AA30: =CONCATENATE(A11," (0 - ",W30," Mp / yr)") -> Mortes, BRISE (0 - 35 milhões/ano) | AB30: =B11/$W30 -> 0.46810243 | AC30: =C11/$W30 -> 0.46399558 | AD30: =D11/$W30 -> 0.4768947 | AE30: =E11/$W30 -> 0.47630951 | AF30: =F11/$W30 -> 0.4938367 | AG30: =G11/$W30 -> 0.50843867 | AH30: =H11/$W30 -> 0.52815823 | AI30: =I11/$W30 -> 0.53896422 | ... AR30: =R11/$W30 -> 0.93849922
U31: =AA31 -> Taxa bruta de natalidade (0 - 4 % / ano) | V31: 4 | W31: =W41 -> 4 | AA31: =CONCATENATE(A12," (0 - ",W31," % / yr)") -> Taxa bruta de natalidade (0 - 4 % / ano) | AB31: =B12/$W31 -> 0.87609981 | AC31: =C12/$W31 -> 0.84042444 | AD31: =D12/$W31 -> 0.79890064 | AE31: =E12/$W31 -> 0.73103197 | AF31: =F12/$W31 -> 0.64757077 | AG31: =G12/$W31 -> 0.57562608 | AH31: =H12/$W31 -> 0.53064374 | AI31: =I12/$W31 -> 0.49586642 | ... AR31: =R12/$W31 -> 0.1875
U32: =AA32 -> Taxa bruta de mortalidade (0 - 2 % / ano) | V32: 2 | W32: =W42 -> 2 | AA32: =CONCATENATE(A13," (0 - ",W32," % / yr)") -> Taxa bruta de mortalidade (0 - 2 % / ano) | AB32: =B13/$W32 -> 0.67880377 | AC32: =C13/$W32 -> 0.60399173 | AD32: =D13/$W32 -> 0.55775318 | AE32: =E13/$W32 -> 0.50153419 | AF32: =F13/$W32 -> 0.47214199 | AG32: =G13/$W32 -> 0.44781884 | AH32: =H13/$W32 -> 0.43305944 | AI32: =I13/$W32 -> 0.41449715 | ... AR32: =R13/$W32 -> 0.60936906
U33: =AA33 -> Previsão de baixa populacional da ONU (0 - 3 Gp) | W33: =W28 -> 3000 | AA33: =CONCATENATE(A21," (0 - ",W33/1000," Gp)") -> Previsão de baixa populacional da ONU (0 - 3 Gp) | AK33: =K21/$W33 -> 0.80993894 | AL33: =L21/$W33 -> 0.83574356 | AM33: =M21/$W33 -> 0.85375739 | AN33: =N21/$W33 -> 0.86661847 | AO33: =O21/$W33 -> 0.87340617 | AP33: =P21/$W33 -> 0.87302399 | AQ33: =Q21/$W33 -> 0.86509979 | AR33: =R21/$W33 -> 0.85011461
U34: =AA34 -> Nascimentos: Previsão baixa da ONU (0 - 50 milhões/ano) | W34: =W29 -> 50 | AA34: =CONCATENATE(A22," (0 - ",W34," Mp / yr)") -> Nascimentos: Previsão baixa da ONU (0 - 50 milhões/ano) | AJ34: =J22/$W34 -> 0.7839867 | AK34: =K22/$W34 -> 0.69159038 | AL34: =L22/$W34 -> 0.61584849 | AM34: =M22/$W34 -> 0.58112429 | AN34: =N22/$W34 -> 0.54177583 | AO34: =O22/$W34 -> 0.49402734 | AP34: =P22/$W34 -> 0.44308087 | AQ34: =Q22/$W34 -> 0.39720765 | AR34: =R22/$W34 -> 0.36090524
U35: =AA35 -> Mortes: Previsão baixa da ONU (0 - 35 milhões/ano) | W35: =W30 -> 35 | AA35: =CONCATENATE(A23," (0 - ",W35," Mp / yr)") -> Mortes: Previsão baixa da ONU (0 - 35 milhões/ano) | AJ35: =J23/$W35 -> 0.54281461 | AK35: =K23/$W35 -> 0.56027208 | AL35: =L23/$W35 -> 0.58732067 | AM35: =M23/$W35 -> 0.62515923 | AN35: =N23/$W35 -> 0.67172412 | AO35: =O23/$W35 -> 0.72521804 | AP35: =P23/$W35 -> 0.78121065 | AQ35: =Q23/$W35 -> 0.83619063 | AR35: =R23/$W35 -> 0.8880575
U36: =AA36 -> Baixa taxa de natalidade da ONU (0 - 4% / ano) | W36: =W31 -> 4 | AA36: =CONCATENATE(A24," (0 - ",W36," % / yr)") -> Baixa taxa de natalidade da ONU (0 - 4% / ano) | AJ36: =J24/$W36 -> 0.40630655 | AK36: =K24/$W36 -> 0.35578319 | AL36: =L24/$W36 -> 0.30703621 | AM36: =M24/$W36 -> 0.28361116 | AN36: =N24/$W36 -> 0.26048364 | AO36: =O24/$W36 -> 0.23568041 | AP36: =P24/$W36 -> 0.21146845 | AQ36: =Q24/$W36 -> 0.1913111 | AR36: =R24/$W36 -> 0.17689048
U37: =AA37 -> Baixa taxa de mortalidade da ONU (0 - 2% / ano) | W37: =W32 -> 2 | AA37: =CONCATENATE(A25," (0 - ",W37," % / yr)") -> Baixa taxa de mortalidade da ONU (0 - 2% / ano) | AJ37: =J25/$W37 -> 0.39384441 | AK37: =K25/$W37 -> 0.40351854 | AL37: =L25/$W37 -> 0.40993881 | AM37: =M25/$W37 -> 0.42714268 | AN37: =N25/$W37 -> 0.45214715 | AO37: =O25/$W37 -> 0.48436097 | AP37: =P25/$W37 -> 0.5219859 | AQ37: =Q25/$W37 -> 0.56384 | AR37: =R25/$W37 -> 0.60936906
U38: =AA38 -> População, BRISE Sua previsão (0 - 3 Gp) | W38: 3000 | AA38: =CONCATENATE(A9," Your forecast (0 - ",W38/1000," Gp)") -> População, BRISE Sua previsão (0 - 3 Gp) | AK38: =K17/$W38 -> 0.84065088 | AL38: =L17/$W38 -> 0.86919533 | AM38: =M17/$W38 -> 0.89177354 | AN38: =N17/$W38 -> 0.9068802 | AO38: =O17/$W38 -> 0.9155768 | AP38: =P17/$W38 -> 0.91698004 | AQ38: =Q17/$W38 -> 0.9105111 | AR38: =R17/$W38 -> 0.89723009
U39: =AA39 -> Nascimentos, BRISE Sua previsão (0 - 50 milhões/ano) | W39: 50 | AA39: =CONCATENATE(A10," Your forecast (0 - ",W39," Mp / yr)") -> Nascimentos, BRISE Sua previsão (0 - 50 milhões/ano) | AJ39: =J18/$W39 -> 0.82005655 | AK39: =K18/$W39 -> 0.74145407 | AL39: =L18/$W39 -> 0.68996725 | AM39: =M18/$W39 -> 0.62923541 | AN39: =N18/$W39 -> 0.58657012 | AO39: =O18/$W39 -> 0.53835916 | AP39: =P18/$W39 -> 0.48526584 | AQ39: =Q18/$W39 -> 0.44436584 | AR39: =R18/$W39 -> 0.39567847
U40: =AA40 -> Mortes, BRISE Sua previsão (0 - 35 milhões/ano) | W40: 35 | AA40: =CONCATENATE(A11," Your forecast (0 - ",W40," Mp / yr)") -> Mortes, BRISE Sua previsão (0 - 35 milhões/ano) | AJ40: =J19/$W40 -> 0.54281461 | AK40: =K19/$W40 -> 0.56988661 | AL40: =L19/$W40 -> 0.59861239 | AM40: =M19/$W40 -> 0.63993643 | AN40: =N19/$W40 -> 0.68887274 | AO40: =O19/$W40 -> 0.74502904 | AP40: =P19/$W40 -> 0.8041331 | AQ40: =Q19/$W40 -> 0.86248273 | AR40: =R19/$W40 -> 0.91853035
...

Sheet  LINHA
A1: =SumWorld!A1 -> Prezado(a) usuário(a): Esta é a versão de 7 de novembro de 2014, às 11h, da planilha de 2052 de Ulrich Goluke (2052@blue-way.net)
A2: =SumWorld!A2 -> Prezado(a) usuário(a): O lado esquerdo desta planilha contém os dados numéricos e os gráficos que você também encontra no livro de 2052. | U2: =SumWorld!U2 -> Prezado(a) usuário(a): Os cálculos nesta parte à direita da planilha garantem o dimensionamento correto dos gráficos.
U3: =SumWorld!U3 -> Contém também a fonte dos dados históricos.
I4: Código de cores | J4: Dados históricos | M4: Sua previsão
A5: LINHA | J5: Previsão de Randers | M5: Calculado a partir da sua previsão.
J6: Valores calculados
A7: =CONCATENATE("Graph 1. Population - ",A5," 1970 to 2050") -> Gráfico 1. População - LINHA DE 1970 a 2050
B8: 1970 | C8: 1975 | D8: 1980 | E8: 1985 | F8: 1990 | G8: 1995 | H8: 2000 | I8: 2005 | J8: 2010 | K8: 2015 | L8: 2020 | M8: 2025 | N8: 2030 | O8: 2035 | P8: 2040 | Q8: 2045 | R8: 2050 | S8: Unidades
A9: População, Resto do Mundo | B9: 862.93834 | C9: 968.74885 | D9: 1093.9292 | E9: 1236.6045 | F9: 1393.9713 | G9: 1557.649 | H9: 1722.9098 | I9: 1896.0258 | J9: 2083.6469 | K9: =J9+(J10-J11)*5 -> 2280.5845 | L9: =K9+(K10-K11)*5 -> 2463.0313 | M9: =L9+(L10-L11)*5 -> 2624.3598 | N9: =M9+(M10-M11)*5 -> 2771.324 | O9: =N9+(N10-N11)*5 -> 2896.0336 | P9: =O9+(O10-O11)*5 -> 2994.4987 | Q9: =P9+(P10-P11)*5 -> 3063.3722 | R9: =Q9+(Q10-Q11)*5 -> 3100.1326 | S9: Deputado | U9: A tabela original foi baixada de http://esa.un.org/unpd/wpp/Excel-Data/DB03_Population_ByAgeSex_Quinquennial/WPP2010_DB3_F1_POPULATION_BY_AGE_BOTH_SEXES.XLS
A10: Nascimentos, ROW | B10: 38.306997 | C10: 42.032034 | D10: 46.593255 | E10: 50.536062 | F10: 53.136588 | G10: 55.208411 | H10: 57.372475 | I10: 60.173784 | J10: =J9*J12/100 -> 58.342112 | K10: =K9*K12/100 -> 57.014613 | L10: =L9*L12/100 -> 54.186688 | M10: =M9*M12/100 -> 52.487196 | N10: =N9*N12/100 -> 49.883831 | O10: =O9*O12/100 -> 46.336537 | P10: =P9*P12/100 -> 41.922982 | Q10: =Q9*Q12/100 -> 36.760466 | R10: =R9*R12/100 -> 31.001326 | S10: Mp/ano | U10: Último acesso em 11 de abril de 2012
A11: Mortes, ROW | B11: 14.582276 | C11: 14.487237 | D11: 15.108773 | E11: 15.869451 | F11: 17.052175 | G11: 18.039106 | H11: 18.401227 | I11: 18.757089 | J11: =J9*J13/100 -> 18.95458 | K11: =K9*K13/100 -> 20.525261 | L11: =L9*L13/100 -> 21.920978 | M11: =M9*M13/100 -> 23.094366 | N11: =N9*N13/100 -> 24.941916 | O11: =O9*O13/100 -> 26.643509 | P11: =P9*P13/100 -> 28.148288 | Q11: =Q9*Q13/100 -> 29.408373 | R11: =R9*R13/100 -> 30.3813 | S11: Mp/ano | U11: Para valores futuros, foi utilizada a variante BAIXA.
A12: taxa bruta de natalidade | B12: =B10/B9*100 -> 4.4391348 | C12: =C10/C9*100 -> 4.3387957 | D12: =D10/D9*100 -> 4.2592568 | E12: =E10/E9*100 -> 4.0866793 | F12: =F10/F9*100 -> 3.8118854 | G12: =G10/G9*100 -> 3.5443422 | H12: =H10/H9*100 -> 3.3299756 | I12: =I10/I9*100 -> 3.1736796 | J12: 2.8 | K12: 2.5 | L12: 2.2 | M12: 2 | N12: 1.8 | O12: 1.6 | P12: 1.4 | Q12: 1.2 | R12: 1 | S12: % por ano
A13: taxa bruta de mortalidade | B13: =B11/B9*100 -> 1.6898398 | C13: =C11/C9*100 -> 1.4954585 | D13: =D11/D9*100 -> 1.3811472 | E13: =E11/E9*100 -> 1.2833085 | F13: =F11/F9*100 -> 1.2232803 | G13: =G11/G9*100 -> 1.1580983 | H13: =H11/H9*100 -> 1.0680319 | I13: =I11/I9*100 -> 0.98928448 | J13: 0.90968293 | K13: 0.9 | L13: 0.89 | M13: 0.88 | N13: 0.9 | O13: 0.92 | P13: 0.94 | Q13: 0.96 | R13: 0.98 | S13: % por ano
A14: Sua previsão
G15: taxa bruta de natalidade | I15: Sua previsão | J15: =J12 -> 2.8 | K15: =K12*0.98 -> 2.45 | L15: =L12*0.98 -> 2.156 | M15: =M12*0.98 -> 1.96 | N15: =N12*0.98 -> 1.764 | O15: =O12*0.98 -> 1.568 | P15: =P12*0.98 -> 1.372 | Q15: =Q12*0.98 -> 1.176 | R15: =R12*0.98 -> 0.98 | S15: % por ano
G16: taxa bruta de mortalidade | I16: Sua previsão | J16: =J13 -> 0.90968293 | K16: =K13*0.98 -> 0.882 | L16: =L13*0.98 -> 0.8722 | M16: =M13*0.98 -> 0.8624 | N16: =N13*0.98 -> 0.882 | O16: =O13*0.98 -> 0.9016 | P16: =P13*0.98 -> 0.9212 | Q16: =Q13*0.98 -> 0.9408 | R16: =R13*0.98 -> 0.9604 | S16: % por ano
I17: População, Resto do Mundo | K17: =J9+(J18-J19)*5 -> 2280.5845 | L17: =K17+(K18-K19)*5 -> 2459.3823 | M17: =L17+(L18-L19)*5 -> 2617.2501 | N17: =M17+(M18-M19)*5 -> 2760.8848 | O17: =N17+(N18-N19)*5 -> 2882.6398 | P17: =O17+(O18-O19)*5 -> 2978.6894 | Q17: =P17+(P18-P19)*5 -> 3045.829 | R17: =Q17+(Q18-Q19)*5 -> 3081.648 | S17: Deputado
I18: Nascimentos, ROW | J18: =J9*J15/100 -> 58.342112 | K18: =K17*K15/100 -> 55.874321 | L18: =L17*L15/100 -> 53.024283 | M18: =M17*M15/100 -> 51.298102 | N18: =N17*N15/100 -> 48.702007 | O18: =O17*O15/100 -> 45.199792 | P18: =P17*P15/100 -> 40.867618 | Q18: =Q17*Q15/100 -> 35.818949 | R18: =R17*R15/100 -> 30.20015 | S18: Mp/ano
I19: Mortes, ROW | J19: =J9*J16/100 -> 18.95458 | K19: =K17*K16/100 -> 20.114755 | L19: =L17*L16/100 -> 21.450733 | M19: =M17*M16/100 -> 22.571165 | N19: =N17*N16/100 -> 24.351004 | O19: =O17*O16/100 -> 25.98988 | P19: =P17*P16/100 -> 27.439686 | Q19: =Q17*Q16/100 -> 28.655159 | R19: =R17*R16/100 -> 29.596147 | S19: Mp/ano
A20: Apenas para fins informativos
A21: Previsão baixa da população da ONU | K21: 2354.2528 | L21: 2531.5859 | M21: 2697.9609 | N21: 2860.204 | O21: 3014.6213 | P21: 3156.2488 | Q21: 3280.5809 | R21: 3385.5771 | S21: Deputado
A22: Nascimentos: baixa previsão da ONU | J22: 58.555203 | K22: 57.475136 | L22: 56.042619 | M22: 56.176628 | N22: 55.789106 | O22: 54.687632 | P22: 52.950547 | Q22: 51.025263 | R22: 49.242284 | S22: Mp/ano
A23: Mortes: previsão baixa da ONU | J23: 18.95458 | K23: 19.51042 | L23: 20.296099 | M23: 21.335876 | N23: 22.638014 | O23: 24.197474 | P23: 25.98821 | Q23: 27.992128 | R23: 30.205929 | S23: Mp/ano
